Workbook

Sheet Config
A1: Additional Configuration
A2: Please select your language: | B2: EN-US

Sheet Exec Summary
B2: These graphs are based off the priorities your organization has assigned to each product in the "SCIMP Plan" tab below (SCIMP = Security, Compliance, Identity, Management and Privacy), and represent total value for the area in the chart title. Detail of your overall maturity can be found in the "Maturity Matrix" tab below.
B4: Realized and Desired Value from current and prospective licensing
C6: Green represents value your are getting from the respective area of techology. It is the combination of what is currently deployed or being deployed (Work in Progress)
C7: Amber represents the total technologies and configurations that your organization can see value in. It is the combination of all technologies that have been given an active deployment priority
C8: Grey represents technologies and configurations that either have not been assessed or your organization sees no value today
B10: Overall view of all technologies (Please note: These include all products and features and exclude configurations, considerations, suggestions and processes)
C11: Overvalue of all Technologies | J11: E3 Current Value | R11: E5 Current Value | X11: Azure Current Value
C12: Realising Value | D12: {=SUM(COUNTIFS('SCIMP Plan'!F3:F241,{"D","W"},'SCIMP Plan'!C3:C241,"Product") + COUNTIFS('SCIMP Plan'!F3:F241,{"D","W"},'SCIMP Plan'!C3:C241,"Feature"))} -> 0 | J12: Realising value from E3 | K12: {=SUM(COUNTIFS('SCIMP Plan'!F3:F241,{"D","W"},'SCIMP Plan'!B3:B241,"*M365 E3*",'SCIMP Plan'!C3:C241,"Feature") + COUNTIFS('SCIMP Plan'!F3:F241,{"D","W"},'SCIMP Plan'!B3:B241,"*M365 E3*",'SCIMP Plan'!C3:C241,"Product"))} -> 0 | R12: Realised Value from E5 | S12: {=SUM(COUNTIFS('SCIMP Plan'!F3:F241,{"D","W"},'SCIMP Plan'!B3:B241,"*M365 Defender*",'SCIMP Plan'!C3:C241,"Feature") + COUNTIFS('SCIMP Plan'!F3:F241,{"D","W"},'SCIMP Plan'!B3:B241,"*M365 Purview*",'SCIMP Plan'!C3:C241,"Product"))} -> 0 | X12: Realising value from Azure Security | Y12: {=SUM(COUNTIFS('SCIMP Plan'!F3:F241,{"D","W"},'SCIMP Plan'!B3:B241,"*Azure*",'SCIMP Plan'!C3:C241,"Feature") + COUNTIFS('SCIMP Plan'!F3:F241,{"D","W"},'SCIMP Plan'!B3:B241,"*Azure*",'SCIMP Plan'!C3:C241,"Product"))} -> 0
C13: Desired Technologies | D13: {=SUM(COUNTIFS('SCIMP Plan'!F3:F241,{"1","2","3"},'SCIMP Plan'!C3:C241,"Product") + COUNTIFS('SCIMP Plan'!F3:F241,{"1","2","3"},'SCIMP Plan'!C3:C241,"Feature"))} -> 0 | J13: Desired E3 Technologies | K13: {=SUM(COUNTIFS('SCIMP Plan'!F3:F241,{"1","2","3"},'SCIMP Plan'!B3:B241,"*M365 E3*",'SCIMP Plan'!C3:C241,"Feature") + COUNTIFS('SCIMP Plan'!F3:F241,{"1","2","3"},'SCIMP Plan'!B3:B241,"*M365 E3*",'SCIMP Plan'!C3:C241,"Product"))} -> 0 | R13: Desired E5 Tech | S13: {=SUM(COUNTIFS('SCIMP Plan'!F3:F241,{"1","2","3"},'SCIMP Plan'!B3:B241,"*M365 Defender*",'SCIMP Plan'!C3:C241,"Feature") + COUNTIFS('SCIMP Plan'!F3:F241,{"1","2","3"},'SCIMP Plan'!B3:B241,"*M365 Purview*",'SCIMP Plan'!C3:C241,"Product")+ COUNTIFS('SCIMP Plan'!F3:F241,{"1","2","3"},'SCIMP Plan'!B3:B241,"*M365 E5*",'SCIMP Plan'!C3:C241,"Product"))} -> 0 | X13: Desired Azure Security Technologies | Y13: {=SUM(COUNTIFS('SCIMP Plan'!F3:F241,{"1","2","3"},'SCIMP Plan'!B3:B241,"*Azure*",'SCIMP Plan'!C3:C241,"Feature") + COUNTIFS('SCIMP Plan'!F3:F241,{"1","2","3"},'SCIMP Plan'!B3:B241,"*Azure*",'SCIMP Plan'!C3:C241,"Product"))} -> 0
C14: No Intent or not yet assessed | D14: {=SUM(COUNTIFS('SCIMP Plan'!F3:F241,{"-","4"},'SCIMP Plan'!C3:C241,"Product") + COUNTIFS('SCIMP Plan'!F3:F241,{"-","4"},'SCIMP Plan'!C3:C241,"Feature"))} -> 151 | J14: Not assessed or superceed by E5 | K14: {=SUM(COUNTIFS('SCIMP Plan'!F3:F241,{"-","4"},'SCIMP Plan'!B3:B241,"*M365 E3*",'SCIMP Plan'!C3:C241,"Feature") + COUNTIFS('SCIMP Plan'!F3:F241,{"-","4"},'SCIMP Plan'!B3:B241,"*M365 E3*",'SCIMP Plan'!C3:C241,"Product"))} -> 58 | R14: Not yet assessed or no intent to deploy | S14: {=SUM(COUNTIFS('SCIMP Plan'!F3:F241,{"-","4"},'SCIMP Plan'!B3:B241,"*M365 Defender*",'SCIMP Plan'!C3:C241,"Feature") + COUNTIFS('SCIMP Plan'!F3:F241,{"-","4"},'SCIMP Plan'!B3:B241,"*M365 Purview*",'SCIMP Plan'!C3:C241,"Product"))} -> 37 | X14: No intent or not yet assessed | Y14: {=SUM(COUNTIFS('SCIMP Plan'!F3:F241,{"-","4"},'SCIMP Plan'!B3:B241,"*Azure*",'SCIMP Plan'!C3:C241,"Feature") + COUNTIFS('SCIMP Plan'!F3:F241,{"-","4"},'SCIMP Plan'!B3:B241,"*Azure*",'SCIMP Plan'!C3:C241,"Product"))} -> 31
K15: E3 | S15: E5 | Y15: Azure
B27: View of Microsoft 365 E5 Technologies (This section shows the current and desired value from all M365 E5 products features)
C31: M365 E5 Core Products | J31: M365 E5 Deeper Product Features | P31: Core Products: These are the individual full products within the respective license
C32: Realised value | D32: {=SUM(COUNTIFS('SCIMP Plan'!F3:F241,{"D","W"},'SCIMP Plan'!B3:B241,{"*M365 Defender*"},'SCIMP Plan'!C3:C241,'Data Validations'!D2) + COUNTIFS('SCIMP Plan'!F3:F241,{"D","W"},'SCIMP Plan'!B3:B241,{"*M365 Purview*"},'SCIMP Plan'!C3:C241,'Data Validations'!D2))} -> 0 | J32: Realised value | K32: {=SUM(COUNTIFS('SCIMP Plan'!F3:F241,{"D","W"},'SCIMP Plan'!B3:B241,{"*M365 Defender*"},'SCIMP Plan'!C3:C241,'Data Validations'!D3) + COUNTIFS('SCIMP Plan'!F3:F241,{"D","W"},'SCIMP Plan'!B3:B241,{"*M365 Purview*"},'SCIMP Plan'!C3:C241,'Data Validations'!D3))} -> 0
C33: Desired Features | D33: {=SUM(COUNTIFS('SCIMP Plan'!F3:F241,{"1","2","3"},'SCIMP Plan'!B3:B241,{"*M365 Defender*"},'SCIMP Plan'!C3:C241,'Data Validations'!D2) + COUNTIFS('SCIMP Plan'!F3:F241,{"1","2","3"},'SCIMP Plan'!B3:B241,{"*M365 Purview"},'SCIMP Plan'!C3:C241,'Data Validations'!D2))} -> 0 | J33: Desired Features | K33: {=SUM(COUNTIFS('SCIMP Plan'!F3:F241,{"1","2","3"},'SCIMP Plan'!B3:B241,{"*M365 Defender*"},'SCIMP Plan'!C3:C241,'Data Validations'!D3) + COUNTIFS('SCIMP Plan'!F3:F241,{"1","2","3"},'SCIMP Plan'!B3:B241,{"*M365 Purview*"},'SCIMP Plan'!C3:C241,'Data Validations'!D3))} -> 0 | P33: Deeper Product Features: These are call out features within a product
C34: Not assessed or no value | D34: {=SUM(COUNTIFS('SCIMP Plan'!F3:F241,{"-","4"},'SCIMP Plan'!B3:B241,{"*M365 Defender*"},'SCIMP Plan'!C3:C241,'Data Validations'!D2) + COUNTIFS('SCIMP Plan'!F3:F241,{"-","4"},'SCIMP Plan'!B3:B241,{"*M365 Purview*"},'SCIMP Plan'!C3:C241,'Data Validations'!D2))} -> 39 | J34: Not assessed or no value | K34: {=SUM(COUNTIFS('SCIMP Plan'!F3:F241,{"-","4"},'SCIMP Plan'!B3:B241,{"*M365 Defender*"},'SCIMP Plan'!C3:C241,'Data Validations'!D3) + COUNTIFS('SCIMP Plan'!F3:F241,{"-","4"},'SCIMP Plan'!B3:B241,{"*M365 Purview*"},'SCIMP Plan'!C3:C241,'Data Validations'!D3))} -> 32
P35: Optional Configuration: These are recommended configurations, considerations, suggestions and process that align to best practices
B44: Break down E5 Security and Compliance SKUs (This sections breaks down the M365 E5 features into E5 Security and E5 Compliance)
C45: M365 E5 Security Core Products | K45: M365 E5 Security Deeper Product Features
C46: Realised value | D46: {=SUM(COUNTIFS('SCIMP Plan'!F3:F241,{"D","W"},'SCIMP Plan'!B3:B241,"*Defender*",'SCIMP Plan'!C3:C241,'Data Validations'!D2))} -> 0 | K46: Realised value | L46: {=SUM(COUNTIFS('SCIMP Plan'!F3:F241,{"D","W"},'SCIMP Plan'!B3:B241,"*Defender*",'SCIMP Plan'!C3:C241,'Data Validations'!D3))} -> 0 | R46: M365 E5 Compliance Core Products
C47: Desired Features | D47: {=SUM(COUNTIFS('SCIMP Plan'!F3:F241,{"1","2","3"},'SCIMP Plan'!B3:B241,"*Defender*",'SCIMP Plan'!C3:C241,'Data Validations'!D2))} -> 0 | K47: Desired Features | L47: {=SUM(COUNTIFS('SCIMP Plan'!F3:F241,{"1","2","3"},'SCIMP Plan'!B3:B241,"*Defender*",'SCIMP Plan'!C3:C241,'Data Validations'!D3))} -> 0 | R47: Realised value | S47: {=SUM(COUNTIFS('SCIMP Plan'!F3:F241,{"D","W"},'SCIMP Plan'!B3:B241,"*Purview*",'SCIMP Plan'!C3:C241,"Product"))} -> 0 | X47: M365 E5 Compliance Deeper Product Features
C48: Not assessed or no value | D48: {=SUM(COUNTIFS('SCIMP Plan'!F3:F241,{"-","4"},'SCIMP Plan'!B3:B241,"*Defender*",'SCIMP Plan'!C3:C241,'Data Validations'!D2))} -> 25 | K48: Not assessed or no value | L48: {=SUM(COUNTIFS('SCIMP Plan'!F3:F241,{"-","4"},'SCIMP Plan'!B3:B241,"*Defender*",'SCIMP Plan'!C3:C241,'Data Validations'!D3))} -> 21 | R48: Desired Features | S48: {=SUM(COUNTIFS('SCIMP Plan'!F3:F241,{"1","2","3"},'SCIMP Plan'!B3:B241,"*Purview*",'SCIMP Plan'!C3:C241,"Product"))} -> 0 | X48: Realised value | Y48: {=SUM(COUNTIFS('SCIMP Plan'!F3:F241,{"D","W"},'SCIMP Plan'!B3:B241,"*Purview*",'SCIMP Plan'!C3:C241,"feature"))} -> 0
R49: Not assessed or no value | S49: {=SUM(COUNTIFS('SCIMP Plan'!F3:F241,{"-","4"},'SCIMP Plan'!B3:B241,"*Purview*",'SCIMP Plan'!C3:C241,"Product"))} -> 16 | X49: Desired Features | Y49: {=SUM(COUNTIFS('SCIMP Plan'!F3:F241,{"1","2","3"},'SCIMP Plan'!B3:B241,"*Purview*",'SCIMP Plan'!C3:C241,"feature"))} -> 0
X50: Not assessed or no value | Y50: {=SUM(COUNTIFS('SCIMP Plan'!F3:F241,{"-","4"},'SCIMP Plan'!B3:B241,"*Purview*",'SCIMP Plan'!C3:C241,"feature"))} -> 11
B61: View of Microsoft 365 E3 Technologies (This section shows the value from E3 products and features as well as alignment to best practice configurations and processes)
D64: E3 Products | K64: E3 Features | S64: E3 Optional Configurations
D65: Realised value | E65: {=SUM(COUNTIFS('SCIMP Plan'!F3:F241,{"D","W"},'SCIMP Plan'!B3:B241,"*M365 E3*",'SCIMP Plan'!C3:C241,"Product"))} -> 0 | K65: Realised value | L65: {=SUM(COUNTIFS('SCIMP Plan'!F3:F241,{"D","W"},'SCIMP Plan'!B3:B241,"*M365 E3*",'SCIMP Plan'!C3:C241,"feature"))} -> 0 | S65: Realised value | T65: {=SUM(COUNTIFS('SCIMP Plan'!F3:F241,{"D","W"},'SCIMP Plan'!B3:B241,"*M365 E3*",'SCIMP Plan'!C3:C241,"Configuration") + COUNTIFS('SCIMP Plan'!F3:F241,{"D","W"},'SCIMP Plan'!B3:B241,"*M365 E3*",'SCIMP Plan'!C3:C241,"Consideration") + COUNTIFS('SCIMP Plan'!F3:F241,{"D","W"},'SCIMP Plan'!B3:B241,"*M365 E3*",'SCIMP Plan'!C3:C241,"Process") + COUNTIFS('SCIMP Plan'!F3:F241,{"D","W"},'SCIMP Plan'!B3:B241,"*M365 E3*",'SCIMP Plan'!C3:C241,"Suggestion"))} -> 0
D66: Desired Features | E66: {=SUM(COUNTIFS('SCIMP Plan'!F3:F241,{"1","2","3"},'SCIMP Plan'!B3:B241,"*M365 E3*",'SCIMP Plan'!C3:C241,"Product"))} -> 0 | K66: Desired Features | L66: {=SUM(COUNTIFS('SCIMP Plan'!F3:F241,{"1","2","3"},'SCIMP Plan'!B3:B241,"*M365 E3*",'SCIMP Plan'!C3:C241,"feature"))} -> 0 | S66: Desired Features | T66: {=SUM(COUNTIFS('SCIMP Plan'!F3:F241,{"1","2","3"},'SCIMP Plan'!B3:B241,"*M365 E3*",'SCIMP Plan'!C3:C241,"Configuration") + COUNTIFS('SCIMP Plan'!F3:F241,{"1","2","3"},'SCIMP Plan'!B3:B241,"*M365 E3*",'SCIMP Plan'!C3:C241,"Consideration") + COUNTIFS('SCIMP Plan'!F3:F241,{"1","2","3"},'SCIMP Plan'!B3:B241,"*M365 E3*",'SCIMP Plan'!C3:C241,"Process") + COUNTIFS('SCIMP Plan'!F3:F241,{"1","2","3"},'SCIMP Plan'!B3:B241,"*M365 E3*",'SCIMP Plan'!C3:C241,"Suggestion"))} -> 0
D67: Not assessed or no value | E67: {=SUM(COUNTIFS('SCIMP Plan'!F3:F241,{"-","4"},'SCIMP Plan'!B3:B241,"*M365 E3*",'SCIMP Plan'!C3:C241,"Product"))} -> 17 | K67: Not assessed or no value | L67: {=SUM(COUNTIFS('SCIMP Plan'!F3:F241,{"-","4"},'SCIMP Plan'!B3:B241,"*M365 E3*",'SCIMP Plan'!C3:C241,"feature"))} -> 41 | S67: Not assessed or no value | T67: {=SUM(COUNTIFS('SCIMP Plan'!F3:F241,{"-","4"},'SCIMP Plan'!B3:B241,"*M365 E3*",'SCIMP Plan'!C3:C241,"Configuration") + COUNTIFS('SCIMP Plan'!F3:F241,{"-","4"},'SCIMP Plan'!B3:B241,"*M365 E3*",'SCIMP Plan'!C3:C241,"Consideration") + COUNTIFS('SCIMP Plan'!F3:F241,{"-","4"},'SCIMP Plan'!B3:B241,"*M365 E3*",'SCIMP Plan'!C3:C241,"Process") + COUNTIFS('SCIMP Plan'!F3:F241,{"-","4"},'SCIMP Plan'!B3:B241,"*M365 E3*",'SCIMP Plan'!C3:C241,"Suggestion"))} -> 39
B79: Current State and Priorites of Solution Areas
C82: Identity | J82: Endpoints | Q82: Threat Protection | X82: Complaince
C83: Deployed | D83: =COUNTIF('SCIMP Plan'!F11:F73,"D") -> 0 | J83: Deployed | K83: =COUNTIF('SCIMP Plan'!F74:F123,"D") -> 0 | Q83: Deployed | R83: =COUNTIF('SCIMP Plan'!F124:F182,"D") -> 0 | X83: Deployed | Y83: =COUNTIF('SCIMP Plan'!F184:F241,"D") -> 0
C84: Work in Progress | D84: =COUNTIF('SCIMP Plan'!F11:F73,"W") -> 0 | J84: Work in Progress | K84: =COUNTIF('SCIMP Plan'!F74:F123,"W") -> 0 | Q84: Work in Progress | R84: =COUNTIF('SCIMP Plan'!F124:F182,"W") -> 0 | X84: Work in Progress | Y84: =COUNTIF('SCIMP Plan'!F184:F241,"W") -> 0
C85: High Priority | D85: =COUNTIF('SCIMP Plan'!F11:F73,"1") -> 0 | J85: High Priority | K85: =COUNTIF('SCIMP Plan'!F74:F123,"1") -> 0 | Q85: High Priority | R85: =COUNTIF('SCIMP Plan'!F124:F182,"1") -> 0 | X85: High Priority | Y85: =COUNTIF('SCIMP Plan'!F184:F241,"1") -> 0
C86: Medium Priority | D86: =COUNTIF('SCIMP Plan'!F11:F73,"2") -> 0 | J86: Medium Priority | K86: =COUNTIF('SCIMP Plan'!F74:F123,"2") -> 0 | Q86: Medium Priority | R86: =COUNTIF('SCIMP Plan'!F124:F182,"2") -> 0 | X86: Medium Priority | Y86: =COUNTIF('SCIMP Plan'!F184:F241,"2") -> 0
C87: Low Priority | D87: =COUNTIF('SCIMP Plan'!F11:F73,"3") -> 0 | J87: Low Priority | K87: =COUNTIF('SCIMP Plan'!F74:F123,"3") -> 0 | Q87: Low Priority | R87: =COUNTIF('SCIMP Plan'!F124:F182,"3") -> 0 | X87: Low Priority | Y87: =COUNTIF('SCIMP Plan'!F184:F241,"3") -> 0
C88: No intent or not yet assessed | D88: {=SUM(COUNTIFS('SCIMP Plan'!F11:F73,{"4","-"}))} -> 55 | J88: No intent or not yet assessed | K88: {=SUM(COUNTIFS('SCIMP Plan'!F74:F123,{"4","-"}))} -> 41 | Q88: No intent | R88: {=SUM(COUNTIFS('SCIMP Plan'!F124:F182,{"4","-"}))} -> 48 | X88: No intent or not yet assessed | Y88: {=SUM(COUNTIF('SCIMP Plan'!F184:F241,{"4","-"}))} -> 51
C97: Blue areas represent the deployed technologies for that solution area, this where you organisation has realised value
C98: Purple areas show "Work in Progress", representing the technologies your organization is currently deploying (in-flight), be that design stages, proof of concept, pilot or full deployment
C99: Green areas represent technologies where you organization sees a definite need (high value) and shows a high intent to deploy
...

Sheet Maturity Matrix
F3: LEGEND:
G5: E3 technologies | J5: E5 Technologies | N5: Azure Subscription | Q5: Standalone Licensing
G7: Priority TBC | J7: Deployed | N7: Work in Progress | Q7: High Priority | T7: Medium Priority | X7: Low Priority | AB7: No intent to deploy
E10: Identity and access management | L10: Endpoints | S10: Threat Protection | Z10: Compliance and Governance
B11: Technical Maturity | D11: Advanced State
G12: Microsoft Entra Identity Protection | J12: Entra Identity Governance: Entitlement Packages | N12: Microsoft Defender Application Control | Q12: Web Content Filtering (MDE-MDCA) | U12: Microsoft Sentinel | X12: MDC - Microsoft Defender for Servers (P2) | AB12: Microsoft Purview Data Catalogue | AE12: Microsoft Priva
G14: Entra Identity Governance: Access Reviews | J14: MDCA: Session Controls | N14: Windows AutoPatch | Q14: Windows 365 | U14: MDC - Microsoft Defender for Storage | X14: MDC - Microsoft Defender for SQL | AB14: Microsoft Purview Data Mapping | AE14: Microsoft Purview Data Connectors
G16: Privilege Identity Management | J16: Privileged Access Management (Exchange) | N16: Advanced Endpoint Analytics | Q16: Endpoint Privilege Management | U16: MDC - Microsoft Defender for Containers | X16: MDC - Microsoft Defender for Key Vault | AB16: Microsoft Purview Insider Risk Management | AE16: Microsoft Purview Communication Compliance
G18: CA: Target Resources (Authenication Context) | J18: Microsoft Entra Permissions Management (CIEM) | U18: MDC - Microsoft Defender for Resource Manager | X18: MDC - Microsoft Defender for DNS | AB18: Trainable Classifers | AE18: Exact Data Match
U20: MDC - Microsoft Defender for App Service | X20: MDC - Microsoft Defender for Open Source DBs | AB20: Microsoft Purview Audit (Premium) | AE20: Microsoft Purview Double Key Encryption
U22: MDC - Microsoft Defender for IoT | X22: MDC - Microsoft Defender for DevOps | AB22: Microsoft Defender for Cloud Apps (Data Governance) | AE22: Microsoft Purview Customer Key
U24: Azure Firewall | X24: Azure Web Application Firewall
U26: Microsoft Defender Threat Intelligence | X26: Azure Front Door
U28: Safe Documents | X28: Microsoft Defender External Attack Surface Management
D30: Medium State
G31: Risk Sign-ins monitoring | J31: Microsoft Entra RBAC Configuration | N31: Microsoft Tunnel | Q31: Intune Tunnel for MAM | U31: Microsoft 365 Defender XDR | X31: Microsoft Threat Experts | AB31: Microsoft Purview Customer Lockbox | AE31: Microsoft Purview eDiscovery (Premium)
G33: Passwordless Authentication | J33: Microsoft Entra App Proxy | N33: ConfigMgr Co-Management Config | Q33: Management of Specialty Devices | U33: Defender for Identity | X33: Microsoft Defender for Cloud Apps (Threat) | AB33: Endpoint DLP | AE33: Microsoft Defender for Cloud Apps (Shadow IT)
G35: Entra ID - Third party SaaS Applications (SSO) | J35: Self Service Group Management | N35: Update ConfigMgr to Current Branch | Q35: Microsoft Defender Exploit Guard (ASR) | U35: Defender for Office 365 | X35: MDC - Microsoft Defender for Servers (P1) | AB35: Microsoft Purview Records Management | AE35: On-premises DLP
G37: HR System Integration | J37: Enable MFA for On-prem services (RADIUS) | N37: Microsoft Defender Application Guard (Edge) | Q37: ConfigMgr -Cloud Management Gateway | U37: MDE for iOS | X37: Attack Simulator v2 | AB37: Purview Labelling Scanner - Classify/Label/Protect | AE37: Teams Data Loss Prevention
G39: Dynamic User Groups | J39: CA: Continuous Access Evaluation | N39: BYOD - Intune Categories | Q39: BYOD: MDM Config (iOS Android) | U39: MDE for Windows Desktops | X39: MDE for Android | AB39: Microsoft Purview Information Protection: Auto Labelling | AE39: Microsoft Purview Compliance Manager
G41: Conditional Access Policies | J41: Process - Assess Secure Score | N41: BYOD: MAM Polices - Mobile OS | Q41: Process - Migrate Apps to Intune | U41: MDE policy configuration | X41: MDE for Mac OS | AB41: Azure Monitor | AE41: Office Message Encryption
G43: CA: Authentication Strength | N43: Windows Hello | Q43: Remote Help | U43: Azure Arc deployment | X43: Defender for Cloud CSPM | AB43: Azure Policy
N45: Endpoint Analytics | Q45: Autopilot Configuration | U45: Azure Bastion | X45: Azure DDoS Protection
D47: Base State
G48: CA: Target Resources (User Actions Device Reg.) | J48: Microsoft Entra Temporary Access Passwords | N48: Windows 10/11 Deployment | Q48: Windows Client Evergreen Plan (WUfB) | U48: Microsoft Defender Antivirus (MDE P1) | X48: Exchange Online Protection | AB48: Microsoft Purview Information Protection: Manual Labelling | AE48: Microsoft Purview Labelling Scanner (Discovery Only)
G50: Microsoft Entra MFA for all users | J50: Self Service Password Reset (SSPR) | N50: Microsoft Defender Credential Guard | Q50: Microsoft Defender System Guard | U50: Office 365 Antimalware Configuration | X50: Secure External Mailflow (TSL, DKIM, DMARC, SPF) | AB50: Microsoft Purview Data Loss Prevention | AE50: Microsoft Purview eDiscovery (Standard)
G52: Conditional Access: Network Assignment | J52: Disable Accounts not used in last 30 days | N52: Windows Firewall | Q52: BitLocker | U52: Do not allow anonymous calendar sharing | X52: Block Client forwarding rules | AB52: Microsoft Purview Data Liftcycle Management | AE52: Microsoft Purview Audit (Standard)
G54: Conditional Access: Block Legacy Auth | J54: Configure Application Consent for Data Access | N54: Corp: MAM Polices - Mobile OS | Q54: Corp: MDM Config (iOS Android) | U54: Transport rules: Block known ransomware files | X54: Configure Teams External Access (Federation) | AB54: Set Organization Level External Sharing settings | AE54: Define Sensitive Information Types
G56: CA: Target Resources (User Actions - Security info) | J56: Microsoft Entra Password Protection | N56: Base Line Compliance Policies | Q56: Corp: MDM Polices - Desktop OS | U56: Configure Teams Guest Access | AB56: Process - Define Classification Schema
G58: Identity Object Remediation | J58: Microsoft Entra Connect Deployment | N58: Unified Write Filter | Q58: Entra Domain Join or Hybrid Domain Join

Sheet SCIMP Plan
A1: Task Name | B1: License | C1: Line Type | D1: Predecessors | E1: NCSC Blueprint | F1: Priority | G1: RAG: Design and Planning | H1: RAG: Admin Configuration | I1: RAG: Deployment Time | J1: RAG: User Change (Impact) | K1: Comment | L1: Microsoft Resource Type | M1: Engagement Type | N1: Recommended use | O1: Key Stakeholder | P1: Risk Register / Audit Report Alignment | Q1: Existing Third party Product | R1: Contract End date | S1: Soft saving category | T1: Business Justification | U1: Resource Type | V1: Management Portal | W1: RBAC Role in Microsoft Entra ID | X1: One Tenant, Multi Organization Scope | Y1: Product Category | Z1: Zero Trust Pillar | AA1: Available with Unified Support (subject to contract) | AB1: Related Value Based Delivery (VBD) ? | AC1: Does the VBD belong to a Designated Engineering package (If so, which one) ? | AD1: Fasttrack Support Offering | AE1: SC Exam | AF1: ESI | AG1: MCAPS
A2: High Level Prerequisites | B2: __ | C2: __ | D2: __ | E2: __ | F2: __ | G2: __ | H2: __ | I2: __ | J2: __ | K2: __ | L2: __ | M2: __ | N2: __ | O2: __ | P2: __ | Q2: __ | R2: __ | S2: __ | T2: =IF(Config!$B$2='Data Validations'!$E$2,Text!B2,IF(Config!$B$2='Data Validations'!$E$3,Text!C2,"Select a lanaguage in config")) -> __ | U2: __ | V2: __ | W2: __ | X2: __ | Y2: __ | Z2: __ | AA2: __
A3: Identity object remediation | B3: M365 E3, M365 F3 | C3: Configuration | F3: - | L3: - | M3: - | N3: - | S3: Operational | T3: =IF(Config!$B$2='Data Validations'!$E$2,Text!B3,IF(Config!$B$2='Data Validations'!$E$3,Text!C3,"Select a lanaguage in config")) -> Allows for synchronisation of on-premises Active Directory accounts into Microsoft Entra ID | U3: Identity | V3: On-premises (ID Fix, dsa.msc) | W3: N/A (On-prem activity) | X3: Organization Specific (on-premises deployment) | Y3: Identity and Access Management | Z3: Identity | AA3: Yes | AD3: Core onboarding: Identity Integration; Microsoft Entra ID: Secure Foundation Infrastructure
A4: Microsoft Entra Connect Deployment (directory synchronization) | B4: M365 E3, M365 F3 | C4: Product | D4: =CONCATENATE(ROW(A3)) -> 3 | F4: - | L4: - | M4: - | N4: - | S4: Operational | T4: =IF(Config!$B$2='Data Validations'!$E$2,Text!B4,IF(Config!$B$2='Data Validations'!$E$3,Text!C4,"Select a lanaguage in config")) -> Creates a relationship between on-premises AD Accounts and AD accounts to make them appear as one account (single identity, effectively a hybrid identity) | U4: Identity, Server Infrastructure | V4: https://portal.azure.com for cloud provisioning | W4: Global Admin | X4: Scoped (Domain, OU, Group filtering) | Y4: Identity and Access Management | Z4: Identity | AA4: Yes | AB4: Onboarding Accelerator – Microsoft Entra ID: Features Deployment (Base) | AC4: Zero Trust: Identity | AD4: Core onboarding: Identity Integration; Microsoft Entra ID: Secure Foundation Infrastructure
A5: Recommended - Configure Password Hash Synchronisation | B5: M365 E3, M365 F3 | C5: Feature | D5: =CONCATENATE(ROW(A3)) -> 3 | E5: Good | F5: - | L5: - | M5: - | N5: - | S5: Productivity | T5: =IF(Config!$B$2='Data Validations'!$E$2,Text!B5,IF(Config!$B$2='Data Validations'!$E$3,Text!C5,"Select a lanaguage in config")) -> Allows for seamless single sign on whilst also removing the need for AD FS servers. This also means no reliance on any servers for authentication on-premises reducing surface area of attack | U5: Identity, Server Infrastructure | V5: On-premises configuration | W5: Global Admin | X5: Organization Specific (Domain Specific) | Y5: Identity and Access Management | Z5: Identity | AA5: Yes | AB5: Zero Trust Foundations Assessment | AC5: Zero Trust: Identity
A6: Microsoft Apps for Enterprise (Office ProPlus) | B6: M365 E3 | C6: Product | D6: =CONCATENATE(ROW(A4)) -> 4 | F6: - | L6: - | M6: - | N6: - | S6: Productivity | T6: =IF(Config!$B$2='Data Validations'!$E$2,Text!B6,IF(Config!$B$2='Data Validations'!$E$3,Text!C6,"Select a lanaguage in config")) -> Always latest and greatest version of Office deployed using the modern Click to Run method. | U6: End User Compute | V6: https://intune.microsoft.com/ | W6: N/A (On-prem activity) | X6: Organization Specific (on-premises deployment) | Y6: Productivity Suite | Z6: Applications | AA6: Yes | AD6: Microsoft 365 Apps; App Assure; Microsoft Teams
A7: Data Migration | B7: _ | C7: _ | D7: _ | E7: _ | F7: - | G7: _ | H7: _ | I7: _ | J7: _ | K7: _ | L7: _ | M7: _ | N7: _ | O7: _ | P7: _ | Q7: _ | R7: _ | S7: _ | T7: =IF(Config!$B$2='Data Validations'!$E$2,Text!B7,IF(Config!$B$2='Data Validations'!$E$3,Text!C7,"Select a lanaguage in config")) -> _ | U7: _ | V7: _ | W7: _ | X7: _ | Y7: _ | Z7: _ | AA7: _
A8: Exchange migration | B8: M365 E3, M365 F3 | C8: Product | D8: =CONCATENATE(ROW(A4)) -> 4 | F8: - | L8: - | M8: - | N8: - | S8: Operational, Productivity | T8: =IF(Config!$B$2='Data Validations'!$E$2,Text!B8,IF(Config!$B$2='Data Validations'!$E$3,Text!C8,"Select a lanaguage in config")) -> Significantly reduce or remove on-premises Exchange servers and all it's associated requirements leaving uses with an always up to date Exchange, access from anywhere, significantly larger mailboxes, transport rules and advanced compliance features on top of other benefits | U8: Active Directory, Exchange, Server infrastructure | V8: https://admin.microsoft.com | W8: Organization Management | X8: Scoped (Domain, OU, Group filtering) | Y8: Email | Z8: Applications | AA8: Yes
A9: SharePoint Migration | B9: M365 E3, M365 F3 | C9: Product | D9: =CONCATENATE(ROW(A4)) -> 4 | F9: - | L9: - | M9: - | N9: - | S9: Operational, Productivity | T9: =IF(Config!$B$2='Data Validations'!$E$2,Text!B9,IF(Config!$B$2='Data Validations'!$E$3,Text!C9,"Select a lanaguage in config")) -> Migrate from legacy file shares to modern document management with SharePoint Online, providing an EDRM system, structured data, better searching, larger storage capacity, better insights, secure access from anywhere and access to advanced compliance features on top of other benefits | U9: Information Governance, Storage, Solutions Architect | V9: https://admin.microsoft.com | W9: SharePoint Administrator | X9: Scoped (Domain, OU, Group filtering) | Y9: Document Management/Internet/EDRMS | Z9: Applications/Data | AA9: Yes | AB9: Activate SharePoint Online Migration MIP | AD9: SPO/ ODfB; Data Migration
A10: OneDrive Migration | B10: M365 E3, M365 F3 | C10: Product | D10: =CONCATENATE(ROW(A4)) -> 4 | F10: - | L10: - | M10: - | N10: - | S10: Operational, Productivity | T10: =IF(Config!$B$2='Data Validations'!$E$2,Text!B10,IF(Config!$B$2='Data Validations'!$E$3,Text!C10,"Select a lanaguage in config")) -> Migrate from legacy home drives to modern document management with OneDrive for Business, providing an EDRM system, structured data, better searching, unlimited storage capacity, secure access from anywhere and access to advanced compliance features on top of other benefits | U10: Information Governance, Storage, Solutions Architect | V10: https://admin.microsoft.com | W10: SharePoint Administrator | X10: Scoped (Domain, OU, Group filtering) | Y10: Document Management/Internet/EDRMS | Z10: Applications/Data | AA10: Yes | AD10: SPO/ ODfB; Data Migration
A11: Identity (Microsoft Entra) | B11: __ | C11: __ | D11: __ | E11: __ | F11: __ | G11: __ | H11: __ | I11: __ | J11: __ | K11: __ | L11: __ | M11: __ | N11: __ | O11: __ | P11: __ | Q11: __ | R11: __ | S11: __ | T11: =IF(Config!$B$2='Data Validations'!$E$2,Text!B11,IF(Config!$B$2='Data Validations'!$E$3,Text!C11,"Select a lanaguage in config")) -> __ | U11: __ | V11: __ | W11: __ | X11: __ | Y11: __ | Z11: __ | AA11: __
A12: Strong Authentication | B12: _ | C12: _ | D12: _ | E12: _ | F12: _ | G12: _ | H12: _ | I12: _ | J12: _ | K12: _ | L12: _ | M12: _ | N12: _ | O12: _ | P12: _ | Q12: _ | R12: _ | S12: _ | T12: =IF(Config!$B$2='Data Validations'!$E$2,Text!B12,IF(Config!$B$2='Data Validations'!$E$3,Text!C12,"Select a lanaguage in config")) -> _ | U12: _ | V12: _ | W12: _ | X12: _ | Y12: _ | Z12: _ | AA12: _ | AB12: WorkshopPLUS - Microsoft Azure: Identity | AC12: Zero Trust: Identity
A13: Microsoft Entra Password Protection | B13: M365 E3, M365 F3 | C13: Feature | D13: =CONCATENATE(ROW(A4)) -> 4 | E13: Good | F13: - | L13: - | M13: - | N13: - | S13: Risk Reduction | T13: =IF(Config!$B$2='Data Validations'!$E$2,Text!B13,IF(Config!$B$2='Data Validations'!$E$3,Text!C13,"Select a lanaguage in config")) -> Stops users from using common passwords and forces them (politely) to set not a only a complex password but one that is more unique and less guessable. In turn this, coupled with MFA, removes the need for users to changes their passwords on a regular basis. This can help reduce load on the helpdesk for forgotten passwords or users physically writing down passwords and taping to desks | U13: Identity, Server Infrastructure | V13: https://entra.microsoft.com | W13: Security Administrator | X13: Tenant Wide | Y13: Identity and Access Management | Z13: Identity | AA13: Yes | AC13: Zero Trust: Identity | AD13: Microsoft Entra ID: Secure Foundation Infrastructure
A14: Microsoft Entra Conditional Access: Network Assignment | B14: M365 E3, M365 F3 | C14: Configuration | D14: =CONCATENATE(ROW(A4)) -> 4 | E14: Good | F14: - | L14: - | M14: - | N14: - | S14: Risk Reduction | T14: =IF(Config!$B$2='Data Validations'!$E$2,Text!B14,IF(Config!$B$2='Data Validations'!$E$3,Text!C14,"Select a lanaguage in config")) -> This has less of a use case in Zero Trust, but can still be used to help validate users when setting up MFA or enrolling devices. I.e., they must pass through physical security before setting up digital security | U14: Identity, Networking | V14: https://entra.microsoft.com | W14: Conditional Access Administrator | X14: Scoped (named locations) | Y14: Identity and Access Management | Z14: Identity | AA14: Yes | AC14: Zero Trust: Identity | AD14: Microsoft Entra ID: Secure Foundation Infrastructure
A15: Microsoft Entra Conditional Access: Target Resources (User Actions - register security information) | B15: M365 E3, M365 F3 | C15: Configuration | D15: =CONCATENATE(ROW(A4)) -> 4 | E15: Good | F15: - | L15: - | M15: - | N15: - | S15: Risk Reduction | T15: =IF(Config!$B$2='Data Validations'!$E$2,Text!B15,IF(Config!$B$2='Data Validations'!$E$3,Text!C15,"Select a lanaguage in config")) -> Allows organizations to define the conditional access conditions a user must go through to enrol into MFA or Self Service Password Reset (SSPR). This helps validate the user is a member of the organization and not an attacker with phished credentials creating trust through MFA | U15: Identity | V15: https://entra.microsoft.com | W15: Conditional Access Administrator | X15: Scoped (to CA policy) | Y15: Identity and Access Management | Z15: Identity | AA15: Yes | AC15: Zero Trust: Identity | AD15: Microsoft Entra ID: Secure Foundation Infrastructure
A16: Microsoft Entra MFA for all users (ZT: Strong Authentication) | B16: M365 E3, M365 F3 | C16: Feature | D16: =CONCATENATE(ROW(A4)) -> 4 | E16: Good | F16: - | L16: - | M16: - | N16: - | S16: Risk Reduction | T16: =IF(Config!$B$2='Data Validations'!$E$2,Text!B16,IF(Config!$B$2='Data Validations'!$E$3,Text!C16,"Select a lanaguage in config")) -> Stops 99.9% of Identity based attacks. As identity is the control plane, MFA is essential protection. Factors of authentication are broken down into something you know (password/PIN), something you have (i.e. phone or token) and something you are (biometrics). The latter two typically can only exist in one place at a time giving trust that the user who provides these is who they claim to be. | U16: Identity, Helpdesk, End User Compute | V16: https://entra.microsoft.com | W16: Authentication Administrator | X16: Organization Specific (Administrative Units) | Y16: Identity and Access Management | Z16: Identity | AA16: Yes | AC16: Zero Trust: Identity | AD16: Microsoft Entra ID: Secure Foundation Infrastructure
A17: Microsoft Entra Combined Registration (SSPR and MFA-R) | B17: M365 E3, M365 F3 | C17: Feature | D17: =CONCATENATE(ROW(A16)) -> 16 | F17: - | L17: - | M17: - | N17: - | S17: Operational, Risk Reduction, Productivity | T17: =IF(Config!$B$2='Data Validations'!$E$2,Text!B17,IF(Config!$B$2='Data Validations'!$E$3,Text!C17,"Select a lanaguage in config")) -> Can significantly reduce load on the help desk by allowing users to reset their own passwords. Provides greater levels of validation that the user is who they claim to be through MFA when resetting passwords. Also allows a user to reset their password anytime, even outside of helpdesk operating hours. Can also be used as a response action, in line with Azure Identity Protection, to help remediate compromised accounts | U17: Identity, Helpdesk, End User Compute | V17: https://entra.microsoft.com | W17: User Administrator + Global Administrator | X17: Tenant wide settings, scoped deployment | Y17: Identity and Access Management | Z17: Identity | AA17: Yes | AC17: Zero Trust: Identity | AD17: Microsoft Entra ID: Secure Foundation infrastructure; Microsoft Entra ID: Automation & Efficiencies
A18: Microsoft Entra Temporary Access Passwords | B18: M365 E3, M365 F3 | C18: Feature | D18: =CONCATENATE(ROW(A4)) -> 4 | E18: Good | F18: - | L18: - | M18: - | N18: - | S18: Operational | T18: =IF(Config!$B$2='Data Validations'!$E$2,Text!B18,IF(Config!$B$2='Data Validations'!$E$3,Text!C18,"Select a lanaguage in config")) -> Primarily used by users go passwordless by validating them as a member of your organization before they setup a passwordless token. In the same vain this can be used to setup MFA for users who cannot come to site or do not yet have a trusted device to setup MFA from. This can also be used as a "get out of jail free card" for users who have "forgotten" MFA devices but not lost them so they can still work for the day. | U18: Identity | V18: https://entra.microsoft.com | W18: Authentication Administrator | X18: Organization Specific (Administrative Units) | Y18: Identity and Access Management | Z18: Identity | AA18: Yes | AC18: Zero Trust: Identity
A19: Passwordless Authentication (ZT: Strong Authentication) | B19: M365 E3, M365 F3 | C19: Feature | D19: =CONCATENATE(ROW(A4)) -> 4 | E19: Good | F19: - | L19: - | M19: - | N19: - | S19: Risk Reduction, Productivity | T19: =IF(Config!$B$2='Data Validations'!$E$2,Text!B19,IF(Config!$B$2='Data Validations'!$E$3,Text!C19,"Select a lanaguage in config")) -> Removes legacy passwords and provides strong, user friendly, non-phishable credentials. The future of authentication | U19: Identity, Helpdesk, End User Compute | V19: https://entra.microsoft.com | W19: Security Administrator + Global Admin | X19: Tenant wide settings, scoped deployment | Y19: Identity and Access Management | Z19: Identity | AA19: Yes | AC19: Zero Trust: Identity
A20: Microsoft Entra Authentication Methods: Certificate-Based Authentication | B20: M365 E3, M365 F3 | C20: Feature | D20: =CONCATENATE(ROW(A4)) -> 4 | F20: - | L20: - | M20: - | N20: - | S20: Operational, Risk Reduction, Productivity | T20: =IF(Config!$B$2='Data Validations'!$E$2,Text!B20,IF(Config!$B$2='Data Validations'!$E$3,Text!C20,"Select a lanaguage in config")) -> Microsoft Entra certificate-based authentication (CBA) enables organizations to configure their Microsoft Entra tenants to allow or require users to authenticate with X.509 certificates created by their Enterprise Public Key Infrastructure (PKI) for app and browser sign-in. This method of authentication is cost effective and secure alterative for users who refuse to use their own device for MFA and cannot be provide with a corporate phone. CBA should also be considered for workload identities. | W20: Global Admin | Y20: Identity and Access Management | Z20: Identity
A21: Microsoft Entra Authentication Methods: OATH Tokens (Preview for HW tokens) | B21: M365 E3, M365 F3 | C21: Feature | D21: =CONCATENATE(ROW(A5)) -> 5 | F21: - | L21: - | M21: - | N21: - | S21: Operational, Risk Reduction, Productivity | T21: =IF(Config!$B$2='Data Validations'!$E$2,Text!B21,IF(Config!$B$2='Data Validations'!$E$3,Text!C21,"Select a lanaguage in config")) -> This hardware OATH token preview improves flexibility and security for organizations by removing Global Administrator requirements. Organizations can delegate token creation, assignment, and activation to Privileged Authentication Administrators or Authentication Policy Administrators. | V21: https://entra.microsoft.com | W21: Authentication Administrator | Y21: Identity and Access Management | Z21: Identity
A22: Microsoft Entra Verified ID | B22: M365 E3, M365 F3, Entra Suite for Face Checks | C22: Product | F22: - | L22: - | M22: - | N22: - | S22: Risk Reduction, Productivity | T22: =IF(Config!$B$2='Data Validations'!$E$2,Text!B22,IF(Config!$B$2='Data Validations'!$E$3,Text!C22,"Select a lanaguage in config")) -> We believe a standards-based Decentralized Identity system can unlock a new set of experiences that give users and organizations greater control over their data—and deliver a higher degree of trust and security for apps, devices, and service providers. | V22: https://entra.microsoft.com | W22: Authentication Administrator | Y22: Identity and Access Management | Z22: Identity
A23: Suggestion - Enable Microsoft Entra MFA for On-prem services (RADIUS) | B23: M365 E3, M365 F3 | C23: Suggestion | D23: =CONCATENATE(ROW(A16)) -> 16 | F23: - | L23: - | M23: - | N23: - | S23: Operational | T23: =IF(Config!$B$2='Data Validations'!$E$2,Text!B23,IF(Config!$B$2='Data Validations'!$E$3,Text!C23,"Select a lanaguage in config")) -> Allows users to use the same additional factors of authentication they use with Azure MFA for on-premises services, such as VPNs and RDP access. Reduces the need to have yet more MFA tokens or other MFA services. | U23: Server infrastructure, Identity, Helpdesk, End User Compute | V23: On-premises configuration | W23: Authentication Policy Administrator | X23: Organization Specific (on-premises deployment) | Y23: Identity and Access Management | Z23: Identity/Applications | AA23: Yes | AC23: Zero Trust: Identity
A24: Conditional Access | B24: _ | C24: _ | D24: _ | E24: _ | F24: _ | G24: _ | H24: _ | I24: _ | J24: _ | K24: _ | L24: _ | M24: _ | N24: _ | O24: _ | P24: _ | Q24: _ | R24: _ | S24: _ | T24: =IF(Config!$B$2='Data Validations'!$E$2,Text!B24,IF(Config!$B$2='Data Validations'!$E$3,Text!C24,"Select a lanaguage in config")) -> _ | U24: _ | V24: _ | W24: _ | X24: _ | Y24: _ | Z24: _ | AA24: _ | AB24: Activate Azure with Multi-Factor Authentication and Conditional Access | AC24: Zero Trust: Identity
A25: Microsoft Entra Conditional Access: Block Legacy Authentication | B25: M365 E3, M365 F3 | C25: Configuration | D25: =CONCATENATE(ROW(A4),",",ROW(A6),",",ROW(A16)) -> 4,6,16 | E25: Good | F25: - | L25: - | M25: - | N25: - | S25: Risk Reduction | T25: =IF(Config!$B$2='Data Validations'!$E$2,Text!B25,IF(Config!$B$2='Data Validations'!$E$3,Text!C25,"Select a lanaguage in config")) -> Reduces surface area of attacks and stops the use of weak authentication methods that does not support MFA (strong authentication). Allowing legacy authentication in any capacity should be highlight on your risk register | U25: Identity, Security | V25: https://entra.microsoft.com | W25: Conditional Access Administrator | X25: Scoped (to CA policy) | Y25: Identity and Access Management | Z25: Identity/Applications | AA25: Yes | AC25: Zero Trust: Identity
A26: Microsoft Entra Conditional Access: Policies | B26: M365 E3, M365 F3 | C26: Feature | D26: =CONCATENATE(ROW(A16)) -> 16 | E26: Good | F26: - | L26: - | M26: - | N26: - | S26: Risk Reduction, Operational | T26: =IF(Config!$B$2='Data Validations'!$E$2,Text!B26,IF(Config!$B$2='Data Validations'!$E$3,Text!C26,"Select a lanaguage in config")) -> The cornerstone of modern authentication providing adaptive access controls based on users, devices, applications, data and risk. Effectively ensuring that right users have the right level of access based on the levels of controls they can adhere to. i.e., users on a fully managed device and MFA can access rich clients and download data whilst users on unmanaged (BYOPC) devices can be restricted to the browser and session controls can extraction of data) | U26: Identity, Security | V26: https://entra.microsoft.com | W26: Conditional Access Administrator | X26: Scoped (to CA policy) | Y26: Identity and Access Management | Z26: Identity | AA26: Yes | AC26: Zero Trust: Identity | AD26: Microsoft Entra ID: Secure Foundation Infrastructure
A27: Microsoft Entra Identity Protection | B27: M365 Defender Suite, M365 Defender Suite FLW | C27: Product | D27: =CONCATENATE(ROW(A17),",",ROW(A26)) -> 17,26 | E27: Better | F27: - | L27: - | M27: - | N27: - | S27: Risk Reduction, Operational | T27: =IF(Config!$B$2='Data Validations'!$E$2,Text!B27,IF(Config!$B$2='Data Validations'!$E$3,Text!C27,"Select a lanaguage in config")) -> Add risks as a condition to conditional access. Not only can this help work towards your Zero Trust strategy. For example, if risk is set to low with a requirement for MFA for all users, they will get additional MFA prompts. As they build a pattern of behaviour within the service (only seen by the A.I. / ML engines), and conform to this pattern they will be challenged for MFA less and less. This can help improve the user experience (less MFA prompts) whilst maintaining a high level of security. | U27: Identity, Security | V27: https://entra.microsoft.com | W27: Security Administrator | X27: Scoped (to CA policy) | Y27: Identity and Access Management | Z27: Identity | AA27: Yes | AC27: Zero Trust: Identity | AD27: Microsoft Entra ID: Secure Foundation Infrastructure
A28: Microsoft Defender for Cloud Apps (Session Controls) | B28: M365 Defender Suite, M365 Purview Suite, M365 Defender Suite FLW | C28: Product | D28: =CONCATENATE(ROW(A26)) -> 26 | E28: Best | F28: - | L28: - | M28: - | N28: - | S28: Risk Reduction, Operational | T28: =IF(Config!$B$2='Data Validations'!$E$2,Text!B28,IF(Config!$B$2='Data Validations'!$E$3,Text!C28,"Select a lanaguage in config")) -> Brings more control for BYOD (especially BOYPC) and external users. Limits sessions on unmanaged devices to browser, controlling/blocking the transfer of data in and out of your environment | U28: Identity, Security, End User Compute | V28: https://security.microsoft.com | W28: Security Administrator | X28: Scoped (to CA policy) | Y28: Identity and Access Management | Z28: Identity | AA28: Yes | AC28: Zero Trust: Identity
A29: Assess Continuous Access Evaluation | B29: M365 E3, M365 F3 | C29: Configuration | D29: =CONCATENATE(ROW(A26)) -> 26 | F29: - | L29: - | M29: - | N29: - | S29: Risk Reduction | T29: =IF(Config!$B$2='Data Validations'!$E$2,Text!B29,IF(Config!$B$2='Data Validations'!$E$3,Text!C29,"Select a lanaguage in config")) -> Continuously re-evaluates access, enforcing conditional access controls when there is a change (such as a user moving from a trusted location to an untrusted one) rather than relying on session timeouts. Greatly improves security without impacting user experience | V29: https://entra.microsoft.com | W29: Conditional Access Administrator | X29: Scoped (Users and Groups) | Y29: Identity and Access Management | Z29: Identity | AA29: Yes
A30: Microsoft Entra Conditional Access: Target Resources (User Actions - register Device) | B30: M365 E3, M365 F3 | C30: Configuration | D30: =CONCATENATE(ROW(A16)) -> 16 | E30: Good | F30: - | L30: - | M30: - | N30: - | S30: Risk Reduction | T30: =IF(Config!$B$2='Data Validations'!$E$2,Text!B30,IF(Config!$B$2='Data Validations'!$E$3,Text!C30,"Select a lanaguage in config")) -> Provide the conditions under which a user can register a device into Microsoft Entra ID, such as being in a trusted location or requiring MFA - this helps ensure that is a user of your organization enrolling a device and not an attacker trying to gain device trust. | U30: Identity, End User Compute | V30: https://entra.microsoft.com | W30: Authentication Policy Administrator | X30: Tenant Wide | Y30: Identity and Access Management/Device Management | Z30: Identity/Devices | AA30: Yes | AB30: Zero Trust Foundations Assessment | AC30: Zero Trust: Identity | AD30: Intune MAM/MDM/Cloud Attach; Windows 10/11
A31: Microsoft Entra Conditional Access: Authentication Strength | B31: M365 E3, M365 F3 | C31: Configuration | D31: =CONCATENATE(ROW(A16),",",ROW(A26),", OPT:",ROW(A19)) -> 16,26, OPT:19 | F31: - | L31: - | M31: - | N31: - | S31: Risk Reduction, Operational | T31: =IF(Config!$B$2='Data Validations'!$E$2,Text!B31,IF(Config!$B$2='Data Validations'!$E$3,Text!C31,"Select a lanaguage in config")) -> Authentication strength can be set in the grant controls of a conditional access policy. This allows your organization to use stronger authentication methods for more sensitive applications. When used with Authentication Context, your organization can require more strict identity verification for access to specific data. | V31: https://entra.microsoft.com | W31: Conditional Access Administrator | X31: Scoped (to CA policy) | Y31: Identity and Access Management | Z31: Identity | AA31: Yes
A32: Microsoft Entra Conditional Access: Target Resources (Authentication Context) | B32: M365 E3, M365 F3 | C32: Configuration | D32: =CONCATENATE(ROW(A26),",", ROW(A31),",",ROW(A188)," OR ",ROW(A189)) -> 26,31,188 OR 189 | F32: - | L32: - | M32: - | N32: - | S32: Operational, Risk Reduction, Productivity | T32: =IF(Config!$B$2='Data Validations'!$E$2,Text!B32,IF(Config!$B$2='Data Validations'!$E$3,Text!C32,"Select a lanaguage in config")) -> Authentication Context allows you set strict or heavily defined security controls over specific applications and data. For example, users, including guests, can be accessing data in a SharePoint site, but some data might be more sensitive. When applying a label with protection (RMS encryption), this block access to the data in Line of Business applications or break processes. With Authentication context, the access to the data can restricted in Conditional Access. For example, when accessing the specific data within the SharePoint site, the Conditional Access policy may require a compliant device or a stronger Authentication Strength to access. In turn, this can reduce the number of conditional access policies required to great the equivalent level of granular access. | V32: https://entra.microsoft.com and https://compliance.microsoft.com | W32: Conditional Access Administrator | X32: Scoped (to CA policy and Information Protection Label) | Y32: Identity and Access Management | Z32: Identity | AA32: Yes
A33: Microsoft Entra Conditional Access: Workload Identities | B33: Entra Workload Identities Premium | C33: Configuration | F33: - | L33: - | M33: - | N33: - | S33: Operational, Productivity | T33: =IF(Config!$B$2='Data Validations'!$E$2,Text!B33,IF(Config!$B$2='Data Validations'!$E$3,Text!C33,"Select a lanaguage in config")) -> Conditional Access for workload identities enables blocking service principals: from outside of known public IP ranges, based on risk detected by Microsoft Entra ID Protection, in combination with authentication contexts. | W33: Conditional Access Administrator | X33: Scoped (to CA policy) | Y33: Identity and Access Management | Z33: Identity | AA33: Yes
A34: Global Secure Access: Microsoft Entra Internet Access - Universal Conditional Access | B34: Entra Suite | C34: Product | D34: =CONCATENATE(ROW(A26)) -> 26 | F34: - | L34: - | M34: - | N34: - | S34: Risk Reduction, Operational | T34: =IF(Config!$B$2='Data Validations'!$E$2,Text!B34,IF(Config!$B$2='Data Validations'!$E$3,Text!C34,"Select a lanaguage in config")) -> In addition to sending traffic to Global Secure Access, administrators can use Conditional Access policies to secure traffic profiles. They can mix and match controls as needed like requiring multifactor authentication, requiring a compliant device, or defining an acceptable sign-in risk. Applying these controls to network traffic not just cloud applications allows for what we call universal Conditional Access. | W34: Global Secure Access Administrator role | X34: Scoped (to CA policy) | Y34: Security Service Edge | Z34: Identity | AA34: Yes
A35: Suggestion - SME Review Conditional Access Policies | B35: N/A | C35: Suggestion | D35: =CONCATENATE(ROW(A26)) -> 26 | F35: - | L35: - | M35: - | N35: - | S35: Operational, Risk Reduction | T35: =IF(Config!$B$2='Data Validations'!$E$2,Text!B35,IF(Config!$B$2='Data Validations'!$E$3,Text!C35,"Select a lanaguage in config")) -> Conditional Access is your frontline for access into your environment, having professional services review and refine your policies can improve your security posture, ensure you are taking a modern approach and potentially improve the end user experience. | U35: External | V35: N/A | W35: N/A | Y35: Professional Services | AA35: Yes | AC35: Zero Trust: Identity
A36: Privilege Management (Cloud Administrators) | B36: _ | C36: _ | D36: _ | E36: _ | F36: _ | G36: _ | H36: _ | I36: _ | J36: _ | K36: _ | L36: _ | M36: _ | N36: _ | O36: _ | P36: _ | Q36: _ | R36: _ | S36: _ | T36: =IF(Config!$B$2='Data Validations'!$E$2,Text!B36,IF(Config!$B$2='Data Validations'!$E$3,Text!C36,"Select a lanaguage in config")) -> _ | U36: _ | V36: _ | W36: _ | X36: _ | Y36: _ | Z36: _ | AA36: _ | AB36: Architectural Service - Microsoft Entra ID: Designing a Secure Cloud Identity | AC36: Zero Trust: Identity
A37: Microsoft Entra RBAC Configuration (ZT: Least Privilege) | B37: M365 E3, M365 F3 | C37: Configuration | D37: =CONCATENATE(ROW(A4)) -> 4 | E37: Good | F37: - | L37: - | M37: - | N37: - | S37: Risk Reduction | T37: =IF(Config!$B$2='Data Validations'!$E$2,Text!B37,IF(Config!$B$2='Data Validations'!$E$3,Text!C37,"Select a lanaguage in config")) -> Following the Zero Trust principal of least privilege, granting your admins only the permissions they require can reduce the impact of breach, both from external attackers and insider threats | U37: Identity, Security, Information Governance | V37: All portals | W37: More information | X37: Scoped (Users and Groups) | Y37: Privileged Access | Z37: Identity | AA37: Yes | AC37: Zero Trust: Identity
A38: Microsoft Entra Privileged Identity Management (ZT: Least Privilege) | B38: M365 Defender Suite, M365 Defender Suite FLW | C38: Product | D38: =CONCATENATE(ROW(A4),",",ROW(A16)) -> 4,16 | E38: Better | F38: - | L38: - | M38: - | N38: - | S38: Risk Reduction | T38: =IF(Config!$B$2='Data Validations'!$E$2,Text!B38,IF(Config!$B$2='Data Validations'!$E$3,Text!C38,"Select a lanaguage in config")) -> Removes privileged standing access and provides auditing and justification around the use of privilege for both internal admins and external support (such as contractors). This significantly reduces your surface area of attack and the damage that can be done in a breach scenario | U38: Identity, Security | V38: https://entra.microsoft.com | W38: Privileged Role Administrator | X38: Scoped (Users and Groups) | Y38: Privileged Access | Z38: Identity | AA38: Yes | AC38: Zero Trust: Identity | AD38: Microsoft Entra ID: Governance
A39: Privileged Access Management (Exchange Online Only) | B39: M365 Defender Suite, M365 Purview Suite, M365 Defender Suite FLW | C39: Product | D39: =CONCATENATE(ROW(A4),",",ROW(A8),",",ROW(A37)) -> 4,8,37 | E39: Better | F39: - | L39: - | M39: - | N39: - | S39: Risk Reduction | T39: =IF(Config!$B$2='Data Validations'!$E$2,Text!B39,IF(Config!$B$2='Data Validations'!$E$3,Text!C39,"Select a lanaguage in config")) -> Provides additional auditing and justification around the most dangerous tasks (such as new-journalrule) that an Exchange admin can run. | U39: Identity, Security, Information Governance | V39: https://admin.microsoft.com | W39: Organization Management | X39: Scoped (Users and Groups) | Y39: Privileged Access | Z39: Identity/Applications | AA39: Yes | AC39: Zero Trust: Identity | AD39: N/A
A40: Conditional Access: Microsoft Admin Portals and Device filters | B40: M365 E3, M365 F3 | C40: Configuration | D40: =CONCATENATE(ROW(A4),",",ROW(A26)) -> 4,26 | F40: - | L40: - | M40: - | N40: - | S40: Operational, Risk Reduction | T40: =IF(Config!$B$2='Data Validations'!$E$2,Text!B40,IF(Config!$B$2='Data Validations'!$E$3,Text!C40,"Select a lanaguage in config")) -> Administrators can add any Microsoft Entra registered application to Conditional Access policies. | U40: Identity, Security | V40: https://entra.microsoft.com | W40: Conditional Access Administrator | X40: Scoped (Users or devices) | Y40: Identity and Access Management | Z40: Identity/Devices | AA40: Yes
...

Sheet Text
A1: Task Name | B1: Business Justification - EN-GB | C1: Business Justification - EN-US
A2: High Level Prerequisites | B2: __ | C2: __
A3: Identity object remediation | B3: Allows for synchronisation of on-premises Active Directory accounts into Microsoft Entra ID | C3: Allows for synchronisation of on-premises Active Directory accounts into Microsoft Entra ID
A4: Microsoft Entra Connect Deployment (directory synchronisation) | B4: Creates a relationship between on-premises AD Accounts and AD accounts to make them appear as one account (single identity, effectively a hybrid identity) | C4: Creates a relationship between on-premises AD Accounts and AD accounts to make them appear as one account (single identity, effectively a hybrid identity)
A5: Recommended - Configure Password Hash Synchronisation | B5: Allows for seamless single sign on whilst also removing the need for AD FS servers. This also means no reliance on any servers for authentication on-premises reducing surface area of attack | C5: Allows for seamless single sign on whilst also removing the need for AD FS servers. This also means no reliance on any servers for authentication on-premises reducing surface area of attack
A6: Microsoft Apps for Enterprise (Office ProPlus) | B6: Always latest and greatest version of Office deployed using the modern Click to Run method. | C6: Always latest and greatest version of Office deployed using the modern Click to Run method.
A7: Data Migration | B7: _ | C7: _
A8: Exchange migration | B8: Significantly reduce or remove on-premises Exchange servers and all it's associated requirements leaving uses with an always up to date Exchange, access from anywhere, significantly larger mailboxes, transport rules and advanced compliance features on top of other benefits | C8: Significantly reduce or remove on-premises Exchange servers and all it's associated requirements leaving uses with an always up to date Exchange, access from anywhere, significantly larger mailboxes, transport rules and advanced compliance features on top of other benefits
A9: SharePoint Migration | B9: Migrate from legacy file shares to modern document management with SharePoint Online, providing an EDRM system, structured data, better searching, larger storage capacity, better insights, secure access from anywhere and access to advanced compliance features on top of other benefits | C9: Migrate from legacy file shares to modern document management with SharePoint Online, providing an EDRM system, structured data, better searching, larger storage capacity, better insights, secure access from anywhere and access to advanced compliance features on top of other benefits
A10: OneDrive Migration | B10: Migrate from legacy home drives to modern document management with OneDrive for Business, providing an EDRM system, structured data, better searching, unlimited storage capacity, secure access from anywhere and access to advanced compliance features on top of other benefits | C10: Migrate from legacy home drives to modern document management with OneDrive for Business, providing an EDRM system, structured data, better searching, unlimited storage capacity, secure access from anywhere and access to advanced compliance features on top of other benefits
A11: Identity (Microsoft Entra) | B11: __ | C11: __
A12: Strong Authentication | B12: _ | C12: _
... A197: Set Organisation Level External Sharing settings | B197: The Organisational External Sharing settings allows organisations to control their guest (external) access to SharePoint and OneDrive, in turn controlling guest management. Although the setting is at the organisation level, individual settings can still be configured on individual sites granting finite controls over more sensitive data. The "Existing Guests" only setting allows for greater governance but more admin overhead. The "New and Existing Guests" can reduce admin overheads but still allow for admin driven controls via groups of guests. | C197: The organizational External Sharing settings allows organizations to control their guest (external) access to SharePoint and OneDrive, in turn controlling guest management. Although the setting is at the organization level, individual settings can still be configured on individual sites granting finite controls over more sensitive data. The "Existing Guests" only setting allows for greater governance but more admin overhead. The "New and Existing Guests" can reduce admin overheads but still allow for admin driven controls via groups of guests.
A198: Microsoft Defender for Cloud Apps (Data Governance)
A199: Microsoft Purview Data Loss Prevention | B199: Organisations have sensitive information under their control such as financial data, intellectual property, health records, or other PII data. To help protect this sensitive data and reduce risk, they need a way to prevent their users from inappropriately sharing it with people who shouldn't have it. This practice is called data loss prevention (DLP). Microsoft Purview Data Loss Prevention can protect data in SharePoint Online (including OneDrive) and Exchange Online. It can also be used with on-premises data flowing through Office 365 via metadata from sensitivity labels. | C199: organizations have sensitive information under their control such as financial data, intellectual property, health records, or other PII data. To help protect this sensitive data and reduce risk, they need a way to prevent their users from inappropriately sharing it with people who shouldn't have it. This practice is called data loss prevention (DLP). Microsoft Purview Data Loss Prevention can protect data in SharePoint Online (including OneDrive) and Exchange Online. It can also be used with on-premises data flowing through Office 365 via metadata from sensitivity labels.
A200: Prevent Accidential Oversharing in Outlook | B200: Force a pop up in Outlook when a user attempts to share sensitive data in a way that matches the respective DLP control, which user can optionally override with justiifcation. This forces the user to check recipients before sending. Suggesting using catch all conditons and the "NOT" condition for exclusions (i.e., no pop up when sending to trusted partners) | C200: Force a pop up in Outlook when a user attempts to share sensitive data in a way that matches the respective DLP control, which user can optionally override with justiifcation. This forces the user to check recipients before sending. Suggesting using catch all conditons and the "NOT" condition for exclusions (i.e., no pop up when sending to trusted partners)
